Workbook

Sheet README
A1: Barcelona pipeline — how to use this workbook
A2: Generated 2026-09-13 from docs/market/barcelona/. Rebuild with: python3 scripts/market-pipeline-xlsx.py
A4: What this is | B4: 128 construction and renovation firms in the Barcelona area, scored and tiered by the roadmap (05-TARGET-LIST.md), with their contact channels, ordered by priority, and a guided sales process from first call to customer. Everything a seller needs is in this one file.
A5: Start here | B5: 1 · Pipeline sheet, filter Focus = Yes (Tier A and B, 37 firms). 2 · Sort by Priority rank. 3 · For each firm read Next action and Script to use — they change with the Stage. 4 · Log every touch in Activity Log. 5 · Move Stage only when the Exit criterion in Playbook is met. 6 · Dashboard shows where the week stands.
A6: Colour legend | B6: YELLOW fill = you fill this in (tracking columns). BLUE text = an input or lever you may change (probabilities, prices). BLACK text = a formula — do not overwrite. Tier colours: A green · B light green · C amber (investment case, not to contact now) · D grey (do not contact, reason given).
A7: Data caveat 1 — contacts | B7: Contact channels are only those the firm PUBLISHES (website, Google listing, marketplace profile, registry). Where a cell is blank, nothing was found by search — do not guess; enrich from SABI/eInforma or a call to the switchboard, then fill it in. Contact coverage per row and for Tier A+B is on the Dashboard.
A8: Data caveat 2 — scores | B8: Every score is capped at 63.6/100: three of five rubric dimensions could not be observed from public data (04-EXTRACTION-QA.md). Tiering is relative, not absolute. The 'Fact that confirms or demotes' column says what a first call must establish. Municipality was wrong in 30.8% of the audited sample — verify it before you drive there.
A9: Data protection | B9: Company-level, published contacts only. Do not add personal mobiles or personal email addresses. Legal basis is legitimate interest for B2B prospecting on published business data (04a-SOURCE-PLAN.md); anyone who objects is marked Lost with reason 'objected' and never contacted again. Before a pilot, the art. 28 processor agreement in Pricing & Pilot must be signed.
A10: What the product cannot promise yet | B10: It is NOT fully Verifactu-compliant on day one (Objection 9). Never say it is. The deadline for an S.L. is 1 January 2027 (03-TRIGGER-MAP.md §1) — re-check on the day of sending.
A11: A demo on their data | B11: Costs 8–16 engineering hours today (07-TAILORING-ECONOMICS.md §4) and two customers cannot yet share one stack. Book engineering before promising a demo; run at most two pilots at once.
A12: Sheets | B12: Dashboard · Pipeline (the list + tracker) · Playbook (stages, what to do, exit criteria, MEDDPICC) · Scripts (ES/CA copy) · Objections · Triggers (openers) · Pricing & Pilot · Activity Log · Lists (hidden dropdowns).
A13: Sources | B13: 05-TARGET-LIST.md (tiers, scores, reasons) · 04-PROSPECTS.jsonl + 04b-CONTACTS.jsonl (firms, contacts) · 06-VALUE-CASE.md (pricing) · 08-GTM-PLAN.md (stages, objections, MEDDPICC) · 09-OUTREACH-KIT.md (scripts) · 03-TRIGGER-MAP.md (openers) · 10-PILOT-SPEC.md (term sheet) · 12-SYNTHESIS.md (stop conditions).
A15: Swatches | B15: You fill in
B16: Input / lever (blue)
B17: Tier A
B18: Tier B
B19: Tier C
B20: Tier D

Sheet Dashboard
A1: Dashboard — where the pipeline stands
A2: All formulas. Nothing to type here.
A4: Firms by tier | D4: Firms by stage | G4: Value
A5: Tier A | B5: =COUNTIF(Pipeline!$B$2:$B$129,"A") -> 7 | D5: Not started | E5: =COUNTIF(Pipeline!$AF$2:$AF$129,"Not started") -> 128 | G5: Pipeline ACV, Focus firms (€) | H5: =SUMIFS(Pipeline!$AS$2:$AS$129,Pipeline!$C$2:$C$129,"Yes") -> 187920
A6: Tier B | B6: =COUNTIF(Pipeline!$B$2:$B$129,"B") -> 30 | D6: Research | E6: =COUNTIF(Pipeline!$AF$2:$AF$129,"Research") -> 0 | G6: Weighted pipeline (€) | H6: =SUM(Pipeline!$AT$2:$AT$129) -> 0
A7: Tier C | B7: =COUNTIF(Pipeline!$B$2:$B$129,"C") -> 13 | D7: Cold call | E7: =COUNTIF(Pipeline!$AF$2:$AF$129,"Cold call") -> 0 | G7: Customers | H7: =COUNTIF(Pipeline!$AF$2:$AF$129,"Customer") -> 0
A8: Tier D | B8: =COUNTIF(Pipeline!$B$2:$B$129,"D") -> 78 | D8: First-touch email | E8: =COUNTIF(Pipeline!$AF$2:$AF$129,"First-touch email") -> 0 | G8: Customer ACV (€) | H8: =SUMIFS(Pipeline!$AS$2:$AS$129,Pipeline!$AF$2:$AF$129,"Customer") -> 0
A9: Focus (A + B) | B9: =COUNTIF(Pipeline!$C$2:$C$129,"Yes") -> 37 | D9: Follow-up 1 | E9: =COUNTIF(Pipeline!$AF$2:$AF$129,"Follow-up 1") -> 0
A10: Focus firms with NO contact channel | B10: =COUNTIFS(Pipeline!$C$2:$C$129,"Yes",Pipeline!$AD$2:$AD$129,0) -> 20 | D10: Follow-up 2 | E10: =COUNTIF(Pipeline!$AF$2:$AF$129,"Follow-up 2") -> 0 | G10: Activity
A11: Focus firms with a phone | B11: =COUNTIFS(Pipeline!$C$2:$C$129,"Yes",Pipeline!$V$2:$V$129,"<>") -> 16 | D11: Meeting booked | E11: =COUNTIF(Pipeline!$AF$2:$AF$129,"Meeting booked") -> 0 | G11: Touches last 7 days | H11: =COUNTIFS('Activity Log'!$A$4:$A$600,">="&(TODAY()-7),'Activity Log'!$A$4:$A$600,"<="&TODAY()) -> 0
A12: Focus firms with an email | B12: =COUNTIFS(Pipeline!$C$2:$C$129,"Yes",Pipeline!$W$2:$W$129,"<>") -> 9 | D12: Meeting held | E12: =COUNTIF(Pipeline!$AF$2:$AF$129,"Meeting held") -> 0 | G12: Touches last 30 days | H12: =COUNTIFS('Activity Log'!$A$4:$A$600,">="&(TODAY()-30),'Activity Log'!$A$4:$A$600,"<="&TODAY()) -> 1
A13: Overdue next actions | B13: =COUNTIF(Pipeline!$AV$2:$AV$129,"OVERDUE") -> 0 | D13: Demo on their data | E13: =COUNTIF(Pipeline!$AF$2:$AF$129,"Demo on their data") -> 0 | G13: Calls, all time | H13: =COUNTIF('Activity Log'!$C$4:$C$600,"Call") -> 1
D14: Pilot proposed | E14: =COUNTIF(Pipeline!$AF$2:$AF$129,"Pilot proposed") -> 0 | G14: Emails, all time | H14: =COUNTIF('Activity Log'!$C$4:$C$600,"Email") -> 0
D15: Pilot running | E15: =COUNTIF(Pipeline!$AF$2:$AF$129,"Pilot running") -> 0 | G15: LinkedIns, all time | H15: =COUNTIF('Activity Log'!$C$4:$C$600,"LinkedIn") -> 0
D16: Customer | E16: =COUNTIF(Pipeline!$AF$2:$AF$129,"Customer") -> 0 | G16: Meetings, all time | H16: =COUNTIF('Activity Log'!$C$4:$C$600,"Meeting") -> 0
D17: Lost | E17: =COUNTIF(Pipeline!$AF$2:$AF$129,"Lost") -> 0 | G17: Demos, all time | H17: =COUNTIF('Activity Log'!$C$4:$C$600,"Demo") -> 0
D18: Not a fit | E18: =COUNTIF(Pipeline!$AF$2:$AF$129,"Not a fit") -> 0 | G18: Proposals, all time | H18: =COUNTIF('Activity Log'!$C$4:$C$600,"Proposal") -> 0
G19: Others, all time | H19: =COUNTIF('Activity Log'!$C$4:$C$600,"Other") -> 0
A20: Stop conditions (12-SYNTHESIS.md, Falsification) — decided before starting
A21: Condition | D21: Live proxy | E21: Now
A22: The list is not a pipeline. If fewer than 12 of the 37 Tier A+B firms can be reached by telephone and confirmed as trading renovation contractors, all outreach stops and the programme goes no further than re-extraction; the red team's rule is "fail experiment 1 and stop". Two thresholds from the same experiment re-sequence rather than stop: fewer than 8 of 37 with four or more live sites means the ICP band is wrong rather than the prospects, and more than 26 of those reached on an unsupported bank puts the N43 adapter ahead of every sales activity. | D22: A+B firms engaged (Stage past Cold call, not Lost/Not a fit) — threshold: at least 12 of 37 | E22: =COUNTIFS(Pipeline!$C$2:$C$129,"Yes",Pipeline!$AF$2:$AF$129,"<>Not started",Pipeline!$AF$2:$AF$129,"<>Research",Pipeline!$AF$2:$AF$129,"<>Cold call",Pipeline!$AF$2:$AF$129,"<>Lost",Pipeline!$AF$2:$AF$129,"<>Not a fit") -> 0
A23: The value case is not real on customer data. If the measured price spread on committed purchases is below 0.5% of third-party spend on both firms _and_ the unbilled-extras share is below 15%, then S2's captured value falls below €25,000 — a 3.9:1 value-to-price ratio, thinner than the 4.7:1 on which Phase 6 already concedes S3 — and the €540-a-month per-site price is withdrawn and the segment is not sold. A measured gestoría retainer below €250 a month for an S2 firm independently invalidates the price ceiling and Phase 6 §4 is rewritten before it is quoted again. | D23: Pilots running or converted — value case is measured on their data during the pilot | E23: =COUNTIF(Pipeline!$AF$2:$AF$129,"Pilot running")+COUNTIF(Pipeline!$AF$2:$AF$129,"Customer") -> 0
A24: The product cannot be delivered at the measured cost, on the path the customer uses. If total delivered hours on one real end-to-end onboarding exceed 40 — 2.5× the measured central of 16 — the L0 cost model, the €2,400 fee, the fee-positive finding and the 46–58% year-one margins are all false and no second pilot starts. Independently, if that firm's bank export cannot be imported without writing code, or the invoice it would actually issue does not carry the persisted rule identifier, legal basis and pack version, compliance is priced at zero in all three segments and outreach halts until the submission channel has hours and an owner. Any one of the three is a stop, not a learning. | D24: Firms at Demo or beyond — each one costs 8–16 engineering hours to build | E24: =COUNTIF(Pipeline!$AF$2:$AF$129,"Demo on their data")+COUNTIF(Pipeline!$AF$2:$AF$129,"Pilot proposed")+COUNTIF(Pipeline!$AF$2:$AF$129,"Pilot running")+COUNTIF(Pipeline!$AF$2:$AF$129,"Customer") -> 0

Sheet Pipeline
A1: Priority rank | B1: Tier | C1: Focus | D1: Segment | E1: Legal name | F1: Trade name | G1: NIF | H1: CNAE | I1: CNAE label | J1: Legal form | K1: Municipality (verify) | L1: Province | M1: Total score | N1: Confidence | O1: Layer | P1: Driving requirement | Q1: Detected triggers | R1: Rationale | S1: Why citable (Tier A) | T1: Fact that confirms or demotes | U1: Reason we lose them | V1: Phone | W1: Email | X1: Website | Y1: Contact form | Z1: LinkedIn (company) | AA1: Contact person (published) | AB1: Maps rating | AC1: Source URLs | AD1: Contact coverage | AE1: Owner | AF1: Stage | AG1: Stage date | AH1: Contact person | AI1: Role | AJ1: Preferred language | AK1: Trigger observed | AL1: Last contact | AM1: Next action due | AN1: Notes | AO1: Next action | AP1: Script to use | AQ1: Exit criterion | AR1: Probability | AS1: ACV (€) | AT1: Weighted (€) | AU1: Days since last contact | AV1: Overdue | AW1: Status
A2: 1 | B2: A | C2: =IF(OR(B2="A",B2="B"),"Yes","No") -> Yes | D2: S1 | E2: A Barcelona Reformas SL | F2: A Barcelona Reformas | G2: B63839583 | H2: 4399 | I2: Other specialised construction activities | J2: S.L. | K2: Barcelona | L2: Barcelona | M2: 63.6 | N2: Medium | O2: L0–L1 | P2: target 43.3/43.9 finishing family | Q2: Sector-default only; contact email is consumer webmail (QA gray-zone, verify before outreach) | R2: S.L. form matches the reference tenant; CNAE 4399 read as sector-confirming. | S2: Reachable by both phone and an owned domain, CNAE-confirmed, and broad enough branding ("A Barcelona Reformas," not a founder's surname) to suggest an established multi-job operation rather than a single-owner outfit — a stronger reference story for the segment than a firm whose name is one person's. | T2: 04-EXTRACTION-QA.md's whole-file audit flags this row's email (barcelonareformas@yahoo.es) as the grey-zone case the GDPR posture itself anticipates — plausibly the firm's own published contact, plausibly not. A call on the phone number confirming trading status and that the yahoo address is genuinely staffed settles it either way. | U2: The webmail address is itself a soft signal against the sale: a firm that answers commercial enquiries from a free consumer account reads as informal at the exact moment it is being pitched a system that replaces informality with structure, and a first written approach to that address risks never being opened. | V2: 932473304 | W2: barcelonareformas@yahoo.es | X2: http://www.reformasbarcelona.info | AC2: https://empresite.eleconomista.es/BARCELONA-REFORMAS.html, https://infonif.economia3.com/ficha-empresa/a-barcelona-reformas-sl, https://www.axesor.es/Informes-Empresas/3168764/A_BARCELONA_REFORMAS_SL.html, https://www.einforma.com/informacion-empresa/barcelona-reformas, https://www.infoconstruccion.es/empresas/a-barcelona-reformas | AD2: =COUNTA(V2:AA2) -> 3 | AF2: Not started | AO2: =IFERROR(INDEX(Playbook!$C$4:$C$17,MATCH($AF2,Playbook!$A$4:$A$17,0)),"") -> Read the row: tier, segment, trigger, reason we lose them. Check contact coverage; if 0, enrich before anything else. | AP2: =IFERROR(INDEX(Playbook!$D$4:$D$17,MATCH($AF2,Playbook!$A$4:$A$17,0)),"") -> — | AQ2: =IFERROR(INDEX(Playbook!$E$4:$E$17,MATCH($AF2,Playbook!$A$4:$A$17,0)),"") -> Row read and a contact channel exists | AR2: =IFERROR(INDEX(Playbook!$G$4:$G$17,MATCH($AF2,Playbook!$A$4:$A$17,0)),0) -> 0 | AS2: =IFERROR(INDEX('Pricing & Pilot'!$D$4:$D$6,MATCH($D2,'Pricing & Pilot'!$A$4:$A$6,0)),0) -> 3600 | AT2: =AS2*AR2 -> 0 | AU2: =IF(AL2="","",TODAY()-AL2) | AV2: =IF(AM2="","",IF(AND(AM2<TODAY(),$AF2<>"Customer",$AF2<>"Lost",$AF2<>"Not a fit"),"OVERDUE","")) | AW2: =IF(AV2="OVERDUE","RED",IF($AF2="Not started","—",IF($AF2="Customer","GREEN",IF(OR($AF2="Lost",$AF2="Not a fit"),"CLOSED","AMBER")))) -> —
A3: 2 | B3: A | C3: =IF(OR(B3="A",B3="B"),"Yes","No") -> Yes | D3: S2 | E3: Delgado & Dilla Construccions I Reformes Integrals SL | F3: Delgado & Dilla Construccions I Reformes Integrals | G3: B64090798 | H3: 4101 | I3: Construction of buildings (developer-builder) | J3: S.L. | K3: Mollet del Vallès | L3: Barcelona | M3: 63.6 | N3: Medium | O3: L0–L1 | P3: renovation-led 41.2 general construction | Q3: Sector-default only (Verifactu 2027 + quarterly filing cycle; no firm-specific signal in this extraction) | R3: S.L. form matches the reference tenant; CNAE 4101 read as sector-confirming. | S3: Registry-verifiable and CNAE-confirmed like the rest of this cohort, but its registered name is written in Catalan ("Construccions I Reformes Integrals," not the Spanish "Construcciones Y Reformas") — the only one of 128 rows where this is true. legal_name is the one field this audit trusts at 0% error, so this is a genuinely observed fact, not an inference, even though it cannot be scored against the rubric's Cultural dimension without a live conversation. | T3: Whether legally binding customer documents must themselves be issued in Catalan — which, if so, triggers the rubric's Catalan-reviewer soft cap (§A.5, soft gate 10) at 80 points, a fact worth knowing before pricing rather than after a contract is signed. | U3: No contact channel of any kind was recovered; a Catalan-first, two-partner firm this size is easy to reach once found, but nothing in this extraction provides the way in. | AC3: https://www.einforma.com/informacion-empresa/delgado-dilla-construccions-reformes-integrals | AD3: =COUNTA(V3:AA3) -> 0 | AF3: Not started | AO3: =IFERROR(INDEX(Playbook!$C$4:$C$17,MATCH($AF3,Playbook!$A$4:$A$17,0)),"") -> Read the row: tier, segment, trigger, reason we lose them. Check contact coverage; if 0, enrich before anything else. | AP3: =IFERROR(INDEX(Playbook!$D$4:$D$17,MATCH($AF3,Playbook!$A$4:$A$17,0)),"") -> — | AQ3: =IFERROR(INDEX(Playbook!$E$4:$E$17,MATCH($AF3,Playbook!$A$4:$A$17,0)),"") -> Row read and a contact channel exists | AR3: =IFERROR(INDEX(Playbook!$G$4:$G$17,MATCH($AF3,Playbook!$A$4:$A$17,0)),0) -> 0 | AS3: =IFERROR(INDEX('Pricing & Pilot'!$D$4:$D$6,MATCH($D3,'Pricing & Pilot'!$A$4:$A$6,0)),0) -> 6480 | AT3: =AS3*AR3 -> 0 | AU3: =IF(AL3="","",TODAY()-AL3) | AV3: =IF(AM3="","",IF(AND(AM3<TODAY(),$AF3<>"Customer",$AF3<>"Lost",$AF3<>"Not a fit"),"OVERDUE","")) | AW3: =IF(AV3="OVERDUE","RED",IF($AF3="Not started","—",IF($AF3="Customer","GREEN",IF(OR($AF3="Lost",$AF3="Not a fit"),"CLOSED","AMBER")))) -> —
A4: 3 | B4: A | C4: =IF(OR(B4="A",B4="B"),"Yes","No") -> Yes | D4: S2 | E4: Edificaciones Y Reformas Mollet 2000 SL | F4: Edificaciones Y Reformas Mollet 2000 | G4: B62393517 | H4: 4121 | I4: Construction of residential buildings | J4: S.L. | K4: Mollet del Vallès | L4: Barcelona | M4: 63.6 | N4: Medium | O4: L0–L1 | P4: renovation-led 41.2 general construction | Q4: Sector-default only; email field duplicates phone (known extraction defect, QA) | R4: S.L. form matches the reference tenant; CNAE 4121 read as sector-confirming. | S4: Registry-verifiable, CNAE-confirmed renovation-led general construction, and a "2000" in the trading name consistent with two and a half decades of trading — an established-SME story, not a two-year-old shell, if the implied founding year holds up. | T4: 04-EXTRACTION-QA.md's mechanical pass caught this exact row's email field holding the same nine digits as its own phone field — a data-entry defect, not a real address. A single call resolves the correct contact channel and confirms current trading status in one step. | U4: The outreach data itself is the risk here, not the firm: a call to a phone number that has since been reassigned or discontinued is the most likely way this one drops out of the pipeline before anyone at the firm is reached. | V4: 935702566 | W4: 935702566 | AC4: https://www.einforma.com/informacion-empresa/edificaciones-reformas-mollet-2000 | AD4: =COUNTA(V4:AA4) -> 2 | AF4: Not started | AO4: =IFERROR(INDEX(Playbook!$C$4:$C$17,MATCH($AF4,Playbook!$A$4:$A$17,0)),"") -> Read the row: tier, segment, trigger, reason we lose them. Check contact coverage; if 0, enrich before anything else. | AP4: =IFERROR(INDEX(Playbook!$D$4:$D$17,MATCH($AF4,Playbook!$A$4:$A$17,0)),"") -> — | AQ4: =IFERROR(INDEX(Playbook!$E$4:$E$17,MATCH($AF4,Playbook!$A$4:$A$17,0)),"") -> Row read and a contact channel exists | AR4: =IFERROR(INDEX(Playbook!$G$4:$G$17,MATCH($AF4,Playbook!$A$4:$A$17,0)),0) -> 0 | AS4: =IFERROR(INDEX('Pricing & Pilot'!$D$4:$D$6,MATCH($D4,'Pricing & Pilot'!$A$4:$A$6,0)),0) -> 6480 | AT4: =AS4*AR4 -> 0 | AU4: =IF(AL4="","",TODAY()-AL4) | AV4: =IF(AM4="","",IF(AND(AM4<TODAY(),$AF4<>"Customer",$AF4<>"Lost",$AF4<>"Not a fit"),"OVERDUE","")) | AW4: =IF(AV4="OVERDUE","RED",IF($AF4="Not started","—",IF($AF4="Customer","GREEN",IF(OR($AF4="Lost",$AF4="Not a fit"),"CLOSED","AMBER")))) -> —
A5: 4 | B5: A | C5: =IF(OR(B5="A",B5="B"),"Yes","No") -> Yes | D5: S1 | E5: Gonzvilarsa S.L. | F5: Gonzvilarsa | G5: B66865254 | H5: 4399 | I5: Other specialised construction activities | J5: S.L. | K5: Sant Joan Despí | L5: Barcelona | M5: 63.6 | N5: Medium | O5: L0–L1 | P5: target 43.3/43.9 finishing family | Q5: Sector-default only (Verifactu 2027 + quarterly filing cycle; no firm-specific signal in this extraction) | R5: S.L. form matches the reference tenant; CNAE 4399 read as sector-confirming. | S5: The best-evidenced row in the entire extraction: CNAE confirmed inside the 43.9x finishing family, S.L., a NIF whose B-prefix is consistent with that form, and — uniquely among the top scorers — an owned domain (gonzvilarsa.com) carrying a working contact email rather than a marketplace listing or a directory mirror. That is the one combination in this list that lets a first outreach start from the firm's own material rather than a registry stub. | T5: A quotation sample or a first call establishing the operations/administration split (02-ICP-AND-RUBRIC.md A.4.2), current job count, and quoting method. Demoted if the domain turns out to be a lead-generation or reseller front rather than an operating contractor with its own crews, or if a live incumbent accounting package surfaces (hard gate 4). | U5: The contact email is generic (contacto@…), not addressed to a named person; a cold message to a shared inbox at a firm this size is the easiest kind of outreach to lose to silence. | V5: 639648153 | W5: contacto@gonzvilarsa.com | X5: https://gonzvilarsa.com | Y5: https://gonzvilarsa.com/contacto | AC5: https://empresite.eleconomista.es/GONZVILARSA.html, https://gonzvilarsa.com/contacto, https://gonzvilarsa.com/sobre-nosotros/, https://www.einforma.com/informacion-empresa/gonzvilarsa | AD5: =COUNTA(V5:AA5) -> 4 | AF5: Not started | AO5: =IFERROR(INDEX(Playbook!$C$4:$C$17,MATCH($AF5,Playbook!$A$4:$A$17,0)),"") -> Read the row: tier, segment, trigger, reason we lose them. Check contact coverage; if 0, enrich before anything else. | AP5: =IFERROR(INDEX(Playbook!$D$4:$D$17,MATCH($AF5,Playbook!$A$4:$A$17,0)),"") -> — | AQ5: =IFERROR(INDEX(Playbook!$E$4:$E$17,MATCH($AF5,Playbook!$A$4:$A$17,0)),"") -> Row read and a contact channel exists | AR5: =IFERROR(INDEX(Playbook!$G$4:$G$17,MATCH($AF5,Playbook!$A$4:$A$17,0)),0) -> 0 | AS5: =IFERROR(INDEX('Pricing & Pilot'!$D$4:$D$6,MATCH($D5,'Pricing & Pilot'!$A$4:$A$6,0)),0) -> 3600 | AT5: =AS5*AR5 -> 0 | AU5: =IF(AL5="","",TODAY()-AL5) | AV5: =IF(AM5="","",IF(AND(AM5<TODAY(),$AF5<>"Customer",$AF5<>"Lost",$AF5<>"Not a fit"),"OVERDUE","")) | AW5: =IF(AV5="OVERDUE","RED",IF($AF5="Not started","—",IF($AF5="Customer","GREEN",IF(OR($AF5="Lost",$AF5="Not a fit"),"CLOSED","AMBER")))) -> —
A6: 5 | B6: A | C6: =IF(OR(B6="A",B6="B"),"Yes","No") -> Yes | D6: S1 | E6: Instalaciones Y Reformas De Calidad SL | F6: Instalaciones Y Reformas De Calidad | G6: B65923849 | H6: 4399 | I6: Other specialised construction activities | J6: S.L. | K6: Badalona | L6: Barcelona | M6: 63.6 | N6: Medium | O6: L0–L1 | P6: target 43.3/43.9 finishing family | Q6: Sector-default only (Verifactu 2027 + quarterly filing cycle; no firm-specific signal in this extraction) | R6: S.L. form matches the reference tenant; CNAE 4399 read as sector-confirming. | S6: Registry-verifiable, CNAE lands inside the target finishing family, and it extends the cohort's geography into the Barcelonès coastal belt (if the unverified municipality holds), which the rest of Tier A does not otherwise cover. | T6: The word "Instalaciones" in the trading name against a 43.99 "other specialised construction" code is exactly the ambiguity Phase 2 §A.5 hard gate 5 warns about: a single revenue-mix question — project work versus recurring maintenance contracts — resolves whether this is a genuine Tier A finishing firm or an installer that should sit in the Tier C pack below. | U6: The same ambiguity that makes this firm worth including is the reason it could be lost badly rather than cleanly: skipping the revenue-mix question and discovering the maintenance majority only after a contract is signed is precisely the failure mode the hard gate exists to prevent. | V6: 935334170 | W6: irc@irc-sl.com | X6: http://irc-sl.com | Y6: http://irc-sl.com/1/contactos_478106.html | AC6: http://irc-sl.com/1/contactos_478106.html, https://www.cylex.es/badalona/instalaciones-y-reformas-de-calidad--s-l--13448547.html, https://www.einforma.com/informacion-empresa/instalaciones-reformas-calidad | AD6: =COUNTA(V6:AA6) -> 4 | AF6: Not started | AO6: =IFERROR(INDEX(Playbook!$C$4:$C$17,MATCH($AF6,Playbook!$A$4:$A$17,0)),"") -> Read the row: tier, segment, trigger, reason we lose them. Check contact coverage; if 0, enrich before anything else. | AP6: =IFERROR(INDEX(Playbook!$D$4:$D$17,MATCH($AF6,Playbook!$A$4:$A$17,0)),"") -> — | AQ6: =IFERROR(INDEX(Playbook!$E$4:$E$17,MATCH($AF6,Playbook!$A$4:$A$17,0)),"") -> Row read and a contact channel exists | AR6: =IFERROR(INDEX(Playbook!$G$4:$G$17,MATCH($AF6,Playbook!$A$4:$A$17,0)),0) -> 0 | AS6: =IFERROR(INDEX('Pricing & Pilot'!$D$4:$D$6,MATCH($D6,'Pricing & Pilot'!$A$4:$A$6,0)),0) -> 3600 | AT6: =AS6*AR6 -> 0 | AU6: =IF(AL6="","",TODAY()-AL6) | AV6: =IF(AM6="","",IF(AND(AM6<TODAY(),$AF6<>"Customer",$AF6<>"Lost",$AF6<>"Not a fit"),"OVERDUE","")) | AW6: =IF(AV6="OVERDUE","RED",IF($AF6="Not started","—",IF($AF6="Customer","GREEN",IF(OR($AF6="Lost",$AF6="Not a fit"),"CLOSED","AMBER")))) -> —
A7: 6 | B7: A | C7: =IF(OR(B7="A",B7="B"),"Yes","No") -> Yes | D7: S2 | E7: Reformas Lluca Les Corts SL | F7: Reformas Lluca Les Corts | G7: B65982332 | H7: 4101 | I7: Construction of buildings (developer-builder) | J7: S.L. | K7: Sabadell | L7: Barcelona | M7: 63.6 | N7: Medium | O7: L0–L1 | P7: renovation-led 41.2 general construction | Q7: Sector-default only (Verifactu 2027 + quarterly filing cycle; no firm-specific signal in this extraction) | R7: S.L. form matches the reference tenant; CNAE 4101 read as sector-confirming. | S7: Registry-verifiable, CNAE-confirmed, and — if the unverified municipality holds — the westernmost firm in the cohort, giving Tier A geographic spread into the Vallès Occidental rather than a cluster around Barcelonès/Baix Llobregat alone. A reference here is an additive proof point, not a restatement of the other six. | T7: The name pairs a Barcelona-city neighbourhood ("Les Corts") with a Sabadell registration — worth a direct registry check on its own terms, given that 04-EXTRACTION-QA.md found exactly this shape of name/location mismatch twice already in this file (rows 67 and 110). | U7: No contact channel was recovered, compounded by the naming mismatch above: this is a firm to verify by registry pull before a call is placed, not after. --- | V7: 936241432 | AC7: https://www.einforma.com/informacion-empresa/reformas-lluca-corts | AD7: =COUNTA(V7:AA7) -> 1 | AF7: Not started | AO7: =IFERROR(INDEX(Playbook!$C$4:$C$17,MATCH($AF7,Playbook!$A$4:$A$17,0)),"") -> Read the row: tier, segment, trigger, reason we lose them. Check contact coverage; if 0, enrich before anything else. | AP7: =IFERROR(INDEX(Playbook!$D$4:$D$17,MATCH($AF7,Playbook!$A$4:$A$17,0)),"") -> — | AQ7: =IFERROR(INDEX(Playbook!$E$4:$E$17,MATCH($AF7,Playbook!$A$4:$A$17,0)),"") -> Row read and a contact channel exists | AR7: =IFERROR(INDEX(Playbook!$G$4:$G$17,MATCH($AF7,Playbook!$A$4:$A$17,0)),0) -> 0 | AS7: =IFERROR(INDEX('Pricing & Pilot'!$D$4:$D$6,MATCH($D7,'Pricing & Pilot'!$A$4:$A$6,0)),0) -> 6480 | AT7: =AS7*AR7 -> 0 | AU7: =IF(AL7="","",TODAY()-AL7) | AV7: =IF(AM7="","",IF(AND(AM7<TODAY(),$AF7<>"Customer",$AF7<>"Lost",$AF7<>"Not a fit"),"OVERDUE","")) | AW7: =IF(AV7="OVERDUE","RED",IF($AF7="Not started","—",IF($AF7="Customer","GREEN",IF(OR($AF7="Lost",$AF7="Not a fit"),"CLOSED","AMBER")))) -> —
A8: 7 | B8: A | C8: =IF(OR(B8="A",B8="B"),"Yes","No") -> Yes | D8: S1 | E8: Reformas Y Construcciones Montcada SL | F8: Reformas Y Construcciones Montcada | G8: B09675620 | H8: 4399 | I8: Other specialised construction activities | J8: S.L. | K8: Montcada i Reixac | L8: Barcelona | M8: 63.6 | N8: Medium | O8: L0–L1 | P8: target 43.3/43.9 finishing family | Q8: Sector-default only (Verifactu 2027 + quarterly filing cycle; no firm-specific signal in this extraction) | R8: S.L. form matches the reference tenant; CNAE 4399 read as sector-confirming. | S8: CNAE-confirmed target sector, S.L., NIF present, and two populated (unweighted, unaudited) context fields — employees_band "1–9" and revenue_band_eur "<1M" — that sit exactly on the ICP's lower edge, where Phase 1 §4.3 says thirty firms scored either side would settle the sweet-spot boundary cheaply. This is that boundary case, found rather than constructed. | T8: Current simultaneous job count, not headcount — Phase 2 §A.1 treats a 5–7-employee firm running three or more jobs at once as acceptable, and the same headcount running one or two jobs as below the serving floor. Job count, not the employee band, is the fact that decides which side of the line this firm sits on. | U8: No phone, email or website was recovered for this row at all; outreach depends entirely on a registered name and address, the slowest channel available and the one most likely to stall before contact is made. | X8: https://reformasycontruccionesmontcada.es/es_es/ | AC8: https://reformasycontruccionesmontcada.es/es_es/, https://www.axesor.es/Informes-Empresas/10469769/REFORMAS_Y_CONSTRUCCIONES_MONTCADA_SL.html, https://www.einforma.com/informacion-empresa/reformas-construcciones-montcada | AD8: =COUNTA(V8:AA8) -> 1 | AF8: Not started | AO8: =IFERROR(INDEX(Playbook!$C$4:$C$17,MATCH($AF8,Playbook!$A$4:$A$17,0)),"") -> Read the row: tier, segment, trigger, reason we lose them. Check contact coverage; if 0, enrich before anything else. | AP8: =IFERROR(INDEX(Playbook!$D$4:$D$17,MATCH($AF8,Playbook!$A$4:$A$17,0)),"") -> — | AQ8: =IFERROR(INDEX(Playbook!$E$4:$E$17,MATCH($AF8,Playbook!$A$4:$A$17,0)),"") -> Row read and a contact channel exists | AR8: =IFERROR(INDEX(Playbook!$G$4:$G$17,MATCH($AF8,Playbook!$A$4:$A$17,0)),0) -> 0 | AS8: =IFERROR(INDEX('Pricing & Pilot'!$D$4:$D$6,MATCH($D8,'Pricing & Pilot'!$A$4:$A$6,0)),0) -> 3600 | AT8: =AS8*AR8 -> 0 | AU8: =IF(AL8="","",TODAY()-AL8) | AV8: =IF(AM8="","",IF(AND(AM8<TODAY(),$AF8<>"Customer",$AF8<>"Lost",$AF8<>"Not a fit"),"OVERDUE","")) | AW8: =IF(AV8="OVERDUE","RED",IF($AF8="Not started","—",IF($AF8="Customer","GREEN",IF(OR($AF8="Lost",$AF8="Not a fit"),"CLOSED","AMBER")))) -> —
A9: 8 | B9: B | C9: =IF(OR(B9="A",B9="B"),"Yes","No") -> Yes | D9: S1 | E9: Aislamientos Gramanet SL | F9: Aislamientos Gramanet | H9: 4342 | I9: Division 43 — specialised construction | J9: S.L. | K9: Santa Coloma de Gramenet | L9: Barcelona | M9: 63.6 | N9: Medium | O9: L0–L1 | P9: target 43.3/43.9 finishing family | Q9: Sector-default only (Verifactu 2027 + quarterly filing cycle; no firm-specific signal in this extraction) | R9: S.L. form matches the reference tenant; CNAE 4342 read as sector-confirming. | U9: No differentiator over the Tier A cohort beyond order of contact — pure reachability risk: someone calls it before we do, or the CNAE/legal-form match turns out wrong on registry check | V9: 933918025 | W9: aisgrasl@gmail.com | X9: https://www.aisgrasl.es | AC9: https://empresite.eleconomista.es/AISLAMIENTOS-GRAMANET.html, https://www.aisgrasl.es/, https://www.einforma.com/informacion-empresa/aislamientos-gramanet | AD9: =COUNTA(V9:AA9) -> 3 | AF9: Not started | AO9: =IFERROR(INDEX(Playbook!$C$4:$C$17,MATCH($AF9,Playbook!$A$4:$A$17,0)),"") -> Read the row: tier, segment, trigger, reason we lose them. Check contact coverage; if 0, enrich before anything else. | AP9: =IFERROR(INDEX(Playbook!$D$4:$D$17,MATCH($AF9,Playbook!$A$4:$A$17,0)),"") -> — | AQ9: =IFERROR(INDEX(Playbook!$E$4:$E$17,MATCH($AF9,Playbook!$A$4:$A$17,0)),"") -> Row read and a contact channel exists | AR9: =IFERROR(INDEX(Playbook!$G$4:$G$17,MATCH($AF9,Playbook!$A$4:$A$17,0)),0) -> 0 | AS9: =IFERROR(INDEX('Pricing & Pilot'!$D$4:$D$6,MATCH($D9,'Pricing & Pilot'!$A$4:$A$6,0)),0) -> 3600 | AT9: =AS9*AR9 -> 0 | AU9: =IF(AL9="","",TODAY()-AL9) | AV9: =IF(AM9="","",IF(AND(AM9<TODAY(),$AF9<>"Customer",$AF9<>"Lost",$AF9<>"Not a fit"),"OVERDUE","")) | AW9: =IF(AV9="OVERDUE","RED",IF($AF9="Not started","—",IF($AF9="Customer","GREEN",IF(OR($AF9="Lost",$AF9="Not a fit"),"CLOSED","AMBER")))) -> —
A10: 9 | B10: B | C10: =IF(OR(B10="A",B10="B"),"Yes","No") -> Yes | D10: S2 | E10: Arquitectura Y Konstruccion De Obras Barcelona SL | F10: Arquitectura Y Konstruccion | H10: 4100 | I10: Division 41 — building construction | J10: S.L. | K10: Barcelona | L10: Barcelona | M10: 63.6 | N10: Medium | O10: L0–L1 | P10: renovation-led 41.2 general construction | Q10: Sector-default only (Verifactu 2027 + quarterly filing cycle; no firm-specific signal in this extraction) | R10: S.L. form matches the reference tenant; CNAE 4100 read as sector-confirming. | U10: No differentiator over the Tier A cohort beyond order of contact — pure reachability risk: someone calls it before we do, or the CNAE/legal-form match turns out wrong on registry check | V10: 934106705 | W10: arkobcn@arkobcn.com | X10: https://arkobcn.com | Y10: https://arkobcn.com/contacto/ | Z10: https://www.linkedin.com/company/arkobcn | AC10: https://arkobcn.com/contacto/, https://es.linkedin.com/company/arkobcn, https://ranking-empresas.eleconomista.es/ARQUITECTURA-KONSTRUCCION-OBRAS-BARCELONA.html, https://www.einforma.com/informacion-empresa/arquitectura-konstruccion-obras-barcelona | AD10: =COUNTA(V10:AA10) -> 5 | AF10: Not started | AO10: =IFERROR(INDEX(Playbook!$C$4:$C$17,MATCH($AF10,Playbook!$A$4:$A$17,0)),"") -> Read the row: tier, segment, trigger, reason we lose them. Check contact coverage; if 0, enrich before anything else. | AP10: =IFERROR(INDEX(Playbook!$D$4:$D$17,MATCH($AF10,Playbook!$A$4:$A$17,0)),"") -> — | AQ10: =IFERROR(INDEX(Playbook!$E$4:$E$17,MATCH($AF10,Playbook!$A$4:$A$17,0)),"") -> Row read and a contact channel exists | AR10: =IFERROR(INDEX(Playbook!$G$4:$G$17,MATCH($AF10,Playbook!$A$4:$A$17,0)),0) -> 0 | AS10: =IFERROR(INDEX('Pricing & Pilot'!$D$4:$D$6,MATCH($D10,'Pricing & Pilot'!$A$4:$A$6,0)),0) -> 6480 | AT10: =AS10*AR10 -> 0 | AU10: =IF(AL10="","",TODAY()-AL10) | AV10: =IF(AM10="","",IF(AND(AM10<TODAY(),$AF10<>"Customer",$AF10<>"Lost",$AF10<>"Not a fit"),"OVERDUE","")) | AW10: =IF(AV10="OVERDUE","RED",IF($AF10="Not started","—",IF($AF10="Customer","GREEN",IF(OR($AF10="Lost",$AF10="Not a fit"),"CLOSED","AMBER")))) -> —
A11: 10 | B11: B | C11: =IF(OR(B11="A",B11="B"),"Yes","No") -> Yes | D11: S2 | E11: BCN Portal Reformas SL | F11: BCN Portal Reformas | H11: 4121 | I11: Construction of residential buildings | J11: S.L. | K11: Barcelona | L11: Barcelona | M11: 63.6 | N11: Medium | O11: L0–L1 | P11: renovation-led 41.2 general construction | Q11: Sector-default only (Verifactu 2027 + quarterly filing cycle; no firm-specific signal in this extraction) | R11: S.L. form matches the reference tenant; CNAE 4121 read as sector-confirming. | U11: No differentiator over the Tier A cohort beyond order of contact — pure reachability risk: someone calls it before we do, or the CNAE/legal-form match turns out wrong on registry check | AC11: https://www.einforma.com/informacion-empresa/bcn-portal-reformas | AD11: =COUNTA(V11:AA11) -> 0 | AF11: Not started | AO11: =IFERROR(INDEX(Playbook!$C$4:$C$17,MATCH($AF11,Playbook!$A$4:$A$17,0)),"") -> Read the row: tier, segment, trigger, reason we lose them. Check contact coverage; if 0, enrich before anything else. | AP11: =IFERROR(INDEX(Playbook!$D$4:$D$17,MATCH($AF11,Playbook!$A$4:$A$17,0)),"") -> — | AQ11: =IFERROR(INDEX(Playbook!$E$4:$E$17,MATCH($AF11,Playbook!$A$4:$A$17,0)),"") -> Row read and a contact channel exists | AR11: =IFERROR(INDEX(Playbook!$G$4:$G$17,MATCH($AF11,Playbook!$A$4:$A$17,0)),0) -> 0 | AS11: =IFERROR(INDEX('Pricing & Pilot'!$D$4:$D$6,MATCH($D11,'Pricing & Pilot'!$A$4:$A$6,0)),0) -> 6480 | AT11: =AS11*AR11 -> 0 | AU11: =IF(AL11="","",TODAY()-AL11) | AV11: =IF(AM11="","",IF(AND(AM11<TODAY(),$AF11<>"Customer",$AF11<>"Lost",$AF11<>"Not a fit"),"OVERDUE","")) | AW11: =IF(AV11="OVERDUE","RED",IF($AF11="Not started","—",IF($AF11="Customer","GREEN",IF(OR($AF11="Lost",$AF11="Not a fit"),"CLOSED","AMBER")))) -> —
A12: 11 | B12: B | C12: =IF(OR(B12="A",B12="B"),"Yes","No") -> Yes | D12: S2 | E12: CARMAREFOR S.L. | F12: Carmarefor | H12: 4121 | I12: Construction of residential buildings | J12: S.L. | K12: Sant Feliu de Llobregat | L12: Barcelona | M12: 63.6 | N12: Medium | O12: L0–L1 | P12: renovation-led 41.2 general construction | Q12: Sector-default only (Verifactu 2027 + quarterly filing cycle; no firm-specific signal in this extraction) | R12: S.L. form matches the reference tenant; CNAE 4121 read as sector-confirming. | U12: No differentiator over the Tier A cohort beyond order of contact — pure reachability risk: someone calls it before we do, or the CNAE/legal-form match turns out wrong on registry check | V12: 931295839 | W12: carma.refor@hotmail.es | AC12: https://www.einforma.com/informacion-empresa/carmarefor, https://www.houzz.es/profesionales/empresas-de-reformas/carmarefor-sl-pfvwes-pf~505590728 | AD12: =COUNTA(V12:AA12) -> 2 | AF12: Not started | AO12: =IFERROR(INDEX(Playbook!$C$4:$C$17,MATCH($AF12,Playbook!$A$4:$A$17,0)),"") -> Read the row: tier, segment, trigger, reason we lose them. Check contact coverage; if 0, enrich before anything else. | AP12: =IFERROR(INDEX(Playbook!$D$4:$D$17,MATCH($AF12,Playbook!$A$4:$A$17,0)),"") -> — | AQ12: =IFERROR(INDEX(Playbook!$E$4:$E$17,MATCH($AF12,Playbook!$A$4:$A$17,0)),"") -> Row read and a contact channel exists | AR12: =IFERROR(INDEX(Playbook!$G$4:$G$17,MATCH($AF12,Playbook!$A$4:$A$17,0)),0) -> 0 | AS12: =IFERROR(INDEX('Pricing & Pilot'!$D$4:$D$6,MATCH($D12,'Pricing & Pilot'!$A$4:$A$6,0)),0) -> 6480 | AT12: =AS12*AR12 -> 0 | AU12: =IF(AL12="","",TODAY()-AL12) | AV12: =IF(AM12="","",IF(AND(AM12<TODAY(),$AF12<>"Customer",$AF12<>"Lost",$AF12<>"Not a fit"),"OVERDUE","")) | AW12: =IF(AV12="OVERDUE","RED",IF($AF12="Not started","—",IF($AF12="Customer","GREEN",IF(OR($AF12="Lost",$AF12="Not a fit"),"CLOSED","AMBER")))) -> —
A13: 12 | B13: B | C13: =IF(OR(B13="A",B13="B"),"Yes","No") -> Yes | D13: S2 | E13: Construcciones Gramasat SL | F13: Construcciones Gramasat | G13: B63763551 | H13: 4102 | I13: Division 41 — building construction | J13: S.L. | K13: Santa Coloma de Gramenet | L13: Barcelona | M13: 63.6 | N13: Medium | O13: L0–L1 | P13: renovation-led 41.2 general construction | Q13: Sector-default only (Verifactu 2027 + quarterly filing cycle; no firm-specific signal in this extraction) | R13: S.L. form matches the reference tenant; CNAE 4102 read as sector-confirming. | U13: No differentiator over the Tier A cohort beyond order of contact — pure reachability risk: someone calls it before we do, or the CNAE/legal-form match turns out wrong on registry check | AC13: https://infonif.economia3.com/ficha-empresa/construcciones-gramasat-sl, https://www.einforma.com/informacion-empresa/construcciones-gramasat | AD13: =COUNTA(V13:AA13) -> 0 | AF13: Not started | AO13: =IFERROR(INDEX(Playbook!$C$4:$C$17,MATCH($AF13,Playbook!$A$4:$A$17,0)),"") -> Read the row: tier, segment, trigger, reason we lose them. Check contact coverage; if 0, enrich before anything else. | AP13: =IFERROR(INDEX(Playbook!$D$4:$D$17,MATCH($AF13,Playbook!$A$4:$A$17,0)),"") -> — | AQ13: =IFERROR(INDEX(Playbook!$E$4:$E$17,MATCH($AF13,Playbook!$A$4:$A$17,0)),"") -> Row read and a contact channel exists | AR13: =IFERROR(INDEX(Playbook!$G$4:$G$17,MATCH($AF13,Playbook!$A$4:$A$17,0)),0) -> 0 | AS13: =IFERROR(INDEX('Pricing & Pilot'!$D$4:$D$6,MATCH($D13,'Pricing & Pilot'!$A$4:$A$6,0)),0) -> 6480 | AT13: =AS13*AR13 -> 0 | AU13: =IF(AL13="","",TODAY()-AL13) | AV13: =IF(AM13="","",IF(AND(AM13<TODAY(),$AF13<>"Customer",$AF13<>"Lost",$AF13<>"Not a fit"),"OVERDUE","")) | AW13: =IF(AV13="OVERDUE","RED",IF($AF13="Not started","—",IF($AF13="Customer","GREEN",IF(OR($AF13="Lost",$AF13="Not a fit"),"CLOSED","AMBER")))) -> —
A14: 13 | B14: B | C14: =IF(OR(B14="A",B14="B"),"Yes","No") -> Yes | D14: S2 | E14: Construcciones Reformas Y Servicios Mataro SL | F14: Construcciones Reformas Y Servicios Mataro | G14: B67185942 | H14: 4121 | I14: Construction of residential buildings | J14: S.L. | K14: Mataró | L14: Barcelona | M14: 63.6 | N14: Medium | O14: L0–L1 | P14: renovation-led 41.2 general construction | Q14: Sector-default only (Verifactu 2027 + quarterly filing cycle; no firm-specific signal in this extraction) | R14: S.L. form matches the reference tenant; CNAE 4121 read as sector-confirming. | U14: No differentiator over the Tier A cohort beyond order of contact — pure reachability risk: someone calls it before we do, or the CNAE/legal-form match turns out wrong on registry check | AC14: https://empresite.eleconomista.es/CONSTRUCCIONES-REFORMAS-SERVICIOS-MATARO.html | AD14: =COUNTA(V14:AA14) -> 0 | AF14: Not started | AO14: =IFERROR(INDEX(Playbook!$C$4:$C$17,MATCH($AF14,Playbook!$A$4:$A$17,0)),"") -> Read the row: tier, segment, trigger, reason we lose them. Check contact coverage; if 0, enrich before anything else. | AP14: =IFERROR(INDEX(Playbook!$D$4:$D$17,MATCH($AF14,Playbook!$A$4:$A$17,0)),"") -> — | AQ14: =IFERROR(INDEX(Playbook!$E$4:$E$17,MATCH($AF14,Playbook!$A$4:$A$17,0)),"") -> Row read and a contact channel exists | AR14: =IFERROR(INDEX(Playbook!$G$4:$G$17,MATCH($AF14,Playbook!$A$4:$A$17,0)),0) -> 0 | AS14: =IFERROR(INDEX('Pricing & Pilot'!$D$4:$D$6,MATCH($D14,'Pricing & Pilot'!$A$4:$A$6,0)),0) -> 6480 | AT14: =AS14*AR14 -> 0 | AU14: =IF(AL14="","",TODAY()-AL14) | AV14: =IF(AM14="","",IF(AND(AM14<TODAY(),$AF14<>"Customer",$AF14<>"Lost",$AF14<>"Not a fit"),"OVERDUE","")) | AW14: =IF(AV14="OVERDUE","RED",IF($AF14="Not started","—",IF($AF14="Customer","GREEN",IF(OR($AF14="Lost",$AF14="Not a fit"),"CLOSED","AMBER")))) -> —
A15: 14 | B15: B | C15: =IF(OR(B15="A",B15="B"),"Yes","No") -> Yes | D15: S2 | E15: Construcciones y Reformas Bonilla S.L. | F15: Construcciones y Reformas Bonilla | G15: B63037907 | H15: 4101 | I15: Construction of buildings (developer-builder) | J15: S.L. | K15: Esplugues de Llobregat | L15: Barcelona | M15: 63.6 | N15: Medium | O15: L0–L1 | P15: renovation-led 41.2 general construction | Q15: Sector-default only (Verifactu 2027 + quarterly filing cycle; no firm-specific signal in this extraction) | R15: S.L. form matches the reference tenant; CNAE 4101 read as sector-confirming. | U15: No differentiator over the Tier A cohort beyond order of contact — pure reachability risk: someone calls it before we do, or the CNAE/legal-form match turns out wrong on registry check | AC15: https://www.einforma.com/informacion-empresa/construcciones-reformas-bonilla | AD15: =COUNTA(V15:AA15) -> 0 | AF15: Not started | AO15: =IFERROR(INDEX(Playbook!$C$4:$C$17,MATCH($AF15,Playbook!$A$4:$A$17,0)),"") -> Read the row: tier, segment, trigger, reason we lose them. Check contact coverage; if 0, enrich before anything else. | AP15: =IFERROR(INDEX(Playbook!$D$4:$D$17,MATCH($AF15,Playbook!$A$4:$A$17,0)),"") -> — | AQ15: =IFERROR(INDEX(Playbook!$E$4:$E$17,MATCH($AF15,Playbook!$A$4:$A$17,0)),"") -> Row read and a contact channel exists | AR15: =IFERROR(INDEX(Playbook!$G$4:$G$17,MATCH($AF15,Playbook!$A$4:$A$17,0)),0) -> 0 | AS15: =IFERROR(INDEX('Pricing & Pilot'!$D$4:$D$6,MATCH($D15,'Pricing & Pilot'!$A$4:$A$6,0)),0) -> 6480 | AT15: =AS15*AR15 -> 0 | AU15: =IF(AL15="","",TODAY()-AL15) | AV15: =IF(AM15="","",IF(AND(AM15<TODAY(),$AF15<>"Customer",$AF15<>"Lost",$AF15<>"Not a fit"),"OVERDUE","")) | AW15: =IF(AV15="OVERDUE","RED",IF($AF15="Not started","—",IF($AF15="Customer","GREEN",IF(OR($AF15="Lost",$AF15="Not a fit"),"CLOSED","AMBER")))) -> —
A16: 15 | B16: B | C16: =IF(OR(B16="A",B16="B"),"Yes","No") -> Yes | D16: S2 | E16: Construcciones Y Reformas Decorhogar SL | F16: Construcciones Y Reformas Decorhogar | H16: 4101 | I16: Construction of buildings (developer-builder) | J16: S.L. | K16: Granollers | L16: Barcelona | M16: 63.6 | N16: Medium | O16: L0–L1 | P16: renovation-led 41.2 general construction | Q16: Sector-default only (Verifactu 2027 + quarterly filing cycle; no firm-specific signal in this extraction) | R16: S.L. form matches the reference tenant; CNAE 4101 read as sector-confirming. | U16: No differentiator over the Tier A cohort beyond order of contact — pure reachability risk: someone calls it before we do, or the CNAE/legal-form match turns out wrong on registry check | V16: 938796333 | AC16: https://www.einforma.com/informacion-empresa/construcciones-reformas-decorhogar, https://www.vipreformas.es/empresa/decorhogar/fa14ace7b3ae2d7e7ee6f1bc3129fbec/ | AD16: =COUNTA(V16:AA16) -> 1 | AF16: Not started | AO16: =IFERROR(INDEX(Playbook!$C$4:$C$17,MATCH($AF16,Playbook!$A$4:$A$17,0)),"") -> Read the row: tier, segment, trigger, reason we lose them. Check contact coverage; if 0, enrich before anything else. | AP16: =IFERROR(INDEX(Playbook!$D$4:$D$17,MATCH($AF16,Playbook!$A$4:$A$17,0)),"") -> — | AQ16: =IFERROR(INDEX(Playbook!$E$4:$E$17,MATCH($AF16,Playbook!$A$4:$A$17,0)),"") -> Row read and a contact channel exists | AR16: =IFERROR(INDEX(Playbook!$G$4:$G$17,MATCH($AF16,Playbook!$A$4:$A$17,0)),0) -> 0 | AS16: =IFERROR(INDEX('Pricing & Pilot'!$D$4:$D$6,MATCH($D16,'Pricing & Pilot'!$A$4:$A$6,0)),0) -> 6480 | AT16: =AS16*AR16 -> 0 | AU16: =IF(AL16="","",TODAY()-AL16) | AV16: =IF(AM16="","",IF(AND(AM16<TODAY(),$AF16<>"Customer",$AF16<>"Lost",$AF16<>"Not a fit"),"OVERDUE","")) | AW16: =IF(AV16="OVERDUE","RED",IF($AF16="Not started","—",IF($AF16="Customer","GREEN",IF(OR($AF16="Lost",$AF16="Not a fit"),"CLOSED","AMBER")))) -> —
A17: 16 | B17: B | C17: =IF(OR(B17="A",B17="B"),"Yes","No") -> Yes | D17: S2 | E17: Construmed Bcn SL | F17: Construmed Bcn | H17: 4100 | I17: Division 41 — building construction | J17: S.L. | K17: Barcelona | L17: Barcelona | M17: 63.6 | N17: Medium | O17: L0–L1 | P17: renovation-led 41.2 general construction | Q17: Sector-default only (Verifactu 2027 + quarterly filing cycle; no firm-specific signal in this extraction) | R17: S.L. form matches the reference tenant; CNAE 4100 read as sector-confirming. | U17: No differentiator over the Tier A cohort beyond order of contact — pure reachability risk: someone calls it before we do, or the CNAE/legal-form match turns out wrong on registry check | AC17: https://infonif.economia3.com/ficha-empresa/construmed-bcn-sl, https://www.einforma.com/informacion-empresa/construmed-bcn | AD17: =COUNTA(V17:AA17) -> 0 | AF17: Not started | AO17: =IFERROR(INDEX(Playbook!$C$4:$C$17,MATCH($AF17,Playbook!$A$4:$A$17,0)),"") -> Read the row: tier, segment, trigger, reason we lose them. Check contact coverage; if 0, enrich before anything else. | AP17: =IFERROR(INDEX(Playbook!$D$4:$D$17,MATCH($AF17,Playbook!$A$4:$A$17,0)),"") -> — | AQ17: =IFERROR(INDEX(Playbook!$E$4:$E$17,MATCH($AF17,Playbook!$A$4:$A$17,0)),"") -> Row read and a contact channel exists | AR17: =IFERROR(INDEX(Playbook!$G$4:$G$17,MATCH($AF17,Playbook!$A$4:$A$17,0)),0) -> 0 | AS17: =IFERROR(INDEX('Pricing & Pilot'!$D$4:$D$6,MATCH($D17,'Pricing & Pilot'!$A$4:$A$6,0)),0) -> 6480 | AT17: =AS17*AR17 -> 0 | AU17: =IF(AL17="","",TODAY()-AL17) | AV17: =IF(AM17="","",IF(AND(AM17<TODAY(),$AF17<>"Customer",$AF17<>"Lost",$AF17<>"Not a fit"),"OVERDUE","")) | AW17: =IF(AV17="OVERDUE","RED",IF($AF17="Not started","—",IF($AF17="Customer","GREEN",IF(OR($AF17="Lost",$AF17="Not a fit"),"CLOSED","AMBER")))) -> —
A18: 17 | B18: B | C18: =IF(OR(B18="A",B18="B"),"Yes","No") -> Yes | D18: S2 | E18: Derribos Y Reformas Terrassa SL | F18: Derribos Y Reformas Terrassa | H18: 41 | I18: Division 41 — building construction | J18: S.L. | K18: Terrassa | L18: Barcelona | M18: 63.6 | N18: Medium | O18: L0–L1 | P18: renovation-led 41.2 general construction | Q18: Sector-default only (Verifactu 2027 + quarterly filing cycle; no firm-specific signal in this extraction) | R18: S.L. form matches the reference tenant; CNAE 41 read as sector-confirming. | U18: No differentiator over the Tier A cohort beyond order of contact — pure reachability risk: someone calls it before we do, or the CNAE/legal-form match turns out wrong on registry check | AC18: https://www.axesor.es/Informes-Empresas/9423521/DERRIBOS_Y_REFORMAS_TERRASSA_SL.html, https://www.einforma.com/informacion-empresa/derribos-reformas-terrassa | AD18: =COUNTA(V18:AA18) -> 0 | AF18: Not started | AO18: =IFERROR(INDEX(Playbook!$C$4:$C$17,MATCH($AF18,Playbook!$A$4:$A$17,0)),"") -> Read the row: tier, segment, trigger, reason we lose them. Check contact coverage; if 0, enrich before anything else. | AP18: =IFERROR(INDEX(Playbook!$D$4:$D$17,MATCH($AF18,Playbook!$A$4:$A$17,0)),"") -> — | AQ18: =IFERROR(INDEX(Playbook!$E$4:$E$17,MATCH($AF18,Playbook!$A$4:$A$17,0)),"") -> Row read and a contact channel exists | AR18: =IFERROR(INDEX(Playbook!$G$4:$G$17,MATCH($AF18,Playbook!$A$4:$A$17,0)),0) -> 0 | AS18: =IFERROR(INDEX('Pricing & Pilot'!$D$4:$D$6,MATCH($D18,'Pricing & Pilot'!$A$4:$A$6,0)),0) -> 6480 | AT18: =AS18*AR18 -> 0 | AU18: =IF(AL18="","",TODAY()-AL18) | AV18: =IF(AM18="","",IF(AND(AM18<TODAY(),$AF18<>"Customer",$AF18<>"Lost",$AF18<>"Not a fit"),"OVERDUE","")) | AW18: =IF(AV18="OVERDUE","RED",IF($AF18="Not started","—",IF($AF18="Customer","GREEN",IF(OR($AF18="Lost",$AF18="Not a fit"),"CLOSED","AMBER")))) -> —
A19: 18 | B19: B | C19: =IF(OR(B19="A",B19="B"),"Yes","No") -> Yes | D19: S2 | E19: Estudios-Reformas Y Mantenimientos SL | F19: Estudios-Reformas Y Mantenimientos | H19: 4101 | I19: Construction of buildings (developer-builder) | J19: S.L. | K19: Barcelona | L19: Barcelona | M19: 63.6 | N19: Medium | O19: L0–L1 | P19: renovation-led 41.2 general construction | Q19: Sector-default only (Verifactu 2027 + quarterly filing cycle; no firm-specific signal in this extraction) | R19: S.L. form matches the reference tenant; CNAE 4101 read as sector-confirming. | U19: No differentiator over the Tier A cohort beyond order of contact — pure reachability risk: someone calls it before we do, or the CNAE/legal-form match turns out wrong on registry check | V19: 934511465 | AC19: https://www.einforma.com/informacion-empresa/estudios-reformas-mantenimientos | AD19: =COUNTA(V19:AA19) -> 1 | AF19: Not started | AO19: =IFERROR(INDEX(Playbook!$C$4:$C$17,MATCH($AF19,Playbook!$A$4:$A$17,0)),"") -> Read the row: tier, segment, trigger, reason we lose them. Check contact coverage; if 0, enrich before anything else. | AP19: =IFERROR(INDEX(Playbook!$D$4:$D$17,MATCH($AF19,Playbook!$A$4:$A$17,0)),"") -> — | AQ19: =IFERROR(INDEX(Playbook!$E$4:$E$17,MATCH($AF19,Playbook!$A$4:$A$17,0)),"") -> Row read and a contact channel exists | AR19: =IFERROR(INDEX(Playbook!$G$4:$G$17,MATCH($AF19,Playbook!$A$4:$A$17,0)),0) -> 0 | AS19: =IFERROR(INDEX('Pricing & Pilot'!$D$4:$D$6,MATCH($D19,'Pricing & Pilot'!$A$4:$A$6,0)),0) -> 6480 | AT19: =AS19*AR19 -> 0 | AU19: =IF(AL19="","",TODAY()-AL19) | AV19: =IF(AM19="","",IF(AND(AM19<TODAY(),$AF19<>"Customer",$AF19<>"Lost",$AF19<>"Not a fit"),"OVERDUE","")) | AW19: =IF(AV19="OVERDUE","RED",IF($AF19="Not started","—",IF($AF19="Customer","GREEN",IF(OR($AF19="Lost",$AF19="Not a fit"),"CLOSED","AMBER")))) -> —
A20: 19 | B20: B | C20: =IF(OR(B20="A",B20="B"),"Yes","No") -> Yes | D20: S2 | E20: JV Reformas En General SL | F20: JV Reformas En General | G20: B44928752 | H20: 4101 | I20: Construction of buildings (developer-builder) | J20: S.L. | K20: Barcelona | L20: Barcelona | M20: 63.6 | N20: Medium | O20: L0–L1 | P20: renovation-led 41.2 general construction | Q20: Sector-default only (Verifactu 2027 + quarterly filing cycle; no firm-specific signal in this extraction) | R20: S.L. form matches the reference tenant; CNAE 4101 read as sector-confirming. | U20: No differentiator over the Tier A cohort beyond order of contact — pure reachability risk: someone calls it before we do, or the CNAE/legal-form match turns out wrong on registry check | AC20: https://www.einforma.com/informacion-empresa/jv-reformas-general | AD20: =COUNTA(V20:AA20) -> 0 | AF20: Not started | AO20: =IFERROR(INDEX(Playbook!$C$4:$C$17,MATCH($AF20,Playbook!$A$4:$A$17,0)),"") -> Read the row: tier, segment, trigger, reason we lose them. Check contact coverage; if 0, enrich before anything else. | AP20: =IFERROR(INDEX(Playbook!$D$4:$D$17,MATCH($AF20,Playbook!$A$4:$A$17,0)),"") -> — | AQ20: =IFERROR(INDEX(Playbook!$E$4:$E$17,MATCH($AF20,Playbook!$A$4:$A$17,0)),"") -> Row read and a contact channel exists | AR20: =IFERROR(INDEX(Playbook!$G$4:$G$17,MATCH($AF20,Playbook!$A$4:$A$17,0)),0) -> 0 | AS20: =IFERROR(INDEX('Pricing & Pilot'!$D$4:$D$6,MATCH($D20,'Pricing & Pilot'!$A$4:$A$6,0)),0) -> 6480 | AT20: =AS20*AR20 -> 0 | AU20: =IF(AL20="","",TODAY()-AL20) | AV20: =IF(AM20="","",IF(AND(AM20<TODAY(),$AF20<>"Customer",$AF20<>"Lost",$AF20<>"Not a fit"),"OVERDUE","")) | AW20: =IF(AV20="OVERDUE","RED",IF($AF20="Not started","—",IF($AF20="Customer","GREEN",IF(OR($AF20="Lost",$AF20="Not a fit"),"CLOSED","AMBER")))) -> —
A21: 20 | B21: B | C21: =IF(OR(B21="A",B21="B"),"Yes","No") -> Yes | D21: S1 | E21: LEM Reforma de Espacios S.L. | F21: LEM Reforma de Espacios | H21: 4399 | I21: Other specialised construction activities | J21: S.L. | K21: L'Hospitalet de Llobregat | L21: Barcelona | M21: 63.6 | N21: Medium | O21: L0–L1 | P21: target 43.3/43.9 finishing family | Q21: Sector-default only (Verifactu 2027 + quarterly filing cycle; no firm-specific signal in this extraction) | R21: S.L. form matches the reference tenant; CNAE 4399 read as sector-confirming. | U21: No differentiator over the Tier A cohort beyond order of contact — pure reachability risk: someone calls it before we do, or the CNAE/legal-form match turns out wrong on registry check | AC21: https://www.einforma.com/informacion-empresa/lem-reforma-espacios | AD21: =COUNTA(V21:AA21) -> 0 | AF21: Not started | AO21: =IFERROR(INDEX(Playbook!$C$4:$C$17,MATCH($AF21,Playbook!$A$4:$A$17,0)),"") -> Read the row: tier, segment, trigger, reason we lose them. Check contact coverage; if 0, enrich before anything else. | AP21: =IFERROR(INDEX(Playbook!$D$4:$D$17,MATCH($AF21,Playbook!$A$4:$A$17,0)),"") -> — | AQ21: =IFERROR(INDEX(Playbook!$E$4:$E$17,MATCH($AF21,Playbook!$A$4:$A$17,0)),"") -> Row read and a contact channel exists | AR21: =IFERROR(INDEX(Playbook!$G$4:$G$17,MATCH($AF21,Playbook!$A$4:$A$17,0)),0) -> 0 | AS21: =IFERROR(INDEX('Pricing & Pilot'!$D$4:$D$6,MATCH($D21,'Pricing & Pilot'!$A$4:$A$6,0)),0) -> 3600 | AT21: =AS21*AR21 -> 0 | AU21: =IF(AL21="","",TODAY()-AL21) | AV21: =IF(AM21="","",IF(AND(AM21<TODAY(),$AF21<>"Customer",$AF21<>"Lost",$AF21<>"Not a fit"),"OVERDUE","")) | AW21: =IF(AV21="OVERDUE","RED",IF($AF21="Not started","—",IF($AF21="Customer","GREEN",IF(OR($AF21="Lost",$AF21="Not a fit"),"CLOSED","AMBER")))) -> —
A22: 21 | B22: B | C22: =IF(OR(B22="A",B22="B"),"Yes","No") -> Yes | D22: S2 | E22: NALSUR Reformas S.L. | F22: NALSUR | G22: B01723030 | H22: 4121 | I22: Construction of residential buildings | J22: S.L. | K22: Cornellà de Llobregat | L22: Barcelona | M22: 63.6 | N22: Medium | O22: L0–L1 | P22: renovation-led 41.2 general construction | Q22: Sector-default only (Verifactu 2027 + quarterly filing cycle; no firm-specific signal in this extraction) | R22: S.L. form matches the reference tenant; CNAE 4121 read as sector-confirming. | U22: No differentiator over the Tier A cohort beyond order of contact — pure reachability risk: someone calls it before we do, or the CNAE/legal-form match turns out wrong on registry check | AC22: https://infonif.economia3.com/ficha-empresa/nalsur-reformas-sl, https://www.einforma.com/informacion-empresa/nalsur-reformas | AD22: =COUNTA(V22:AA22) -> 0 | AF22: Not started | AO22: =IFERROR(INDEX(Playbook!$C$4:$C$17,MATCH($AF22,Playbook!$A$4:$A$17,0)),"") -> Read the row: tier, segment, trigger, reason we lose them. Check contact coverage; if 0, enrich before anything else. | AP22: =IFERROR(INDEX(Playbook!$D$4:$D$17,MATCH($AF22,Playbook!$A$4:$A$17,0)),"") -> — | AQ22: =IFERROR(INDEX(Playbook!$E$4:$E$17,MATCH($AF22,Playbook!$A$4:$A$17,0)),"") -> Row read and a contact channel exists | AR22: =IFERROR(INDEX(Playbook!$G$4:$G$17,MATCH($AF22,Playbook!$A$4:$A$17,0)),0) -> 0 | AS22: =IFERROR(INDEX('Pricing & Pilot'!$D$4:$D$6,MATCH($D22,'Pricing & Pilot'!$A$4:$A$6,0)),0) -> 6480 | AT22: =AS22*AR22 -> 0 | AU22: =IF(AL22="","",TODAY()-AL22) | AV22: =IF(AM22="","",IF(AND(AM22<TODAY(),$AF22<>"Customer",$AF22<>"Lost",$AF22<>"Not a fit"),"OVERDUE","")) | AW22: =IF(AV22="OVERDUE","RED",IF($AF22="Not started","—",IF($AF22="Customer","GREEN",IF(OR($AF22="Lost",$AF22="Not a fit"),"CLOSED","AMBER")))) -> —
A23: 22 | B23: B | C23: =IF(OR(B23="A",B23="B"),"Yes","No") -> Yes | D23: S2 | E23: Obralia Reformas Integrales S.L. | F23: Obralia Reformas Integrales | G23: B22605273 | H23: 4101 | I23: Construction of buildings (developer-builder) | J23: S.L. | K23: Cornellà de Llobregat | L23: Barcelona | M23: 63.6 | N23: Medium | O23: L0–L1 | P23: renovation-led 41.2 general construction | Q23: Sector-default only (Verifactu 2027 + quarterly filing cycle; no firm-specific signal in this extraction) | R23: S.L. form matches the reference tenant; CNAE 4101 read as sector-confirming. | U23: No differentiator over the Tier A cohort beyond order of contact — pure reachability risk: someone calls it before we do, or the CNAE/legal-form match turns out wrong on registry check | AC23: https://www.einforma.com/informacion-empresa/obralia-reformas-integrales | AD23: =COUNTA(V23:AA23) -> 0 | AF23: Not started | AO23: =IFERROR(INDEX(Playbook!$C$4:$C$17,MATCH($AF23,Playbook!$A$4:$A$17,0)),"") -> Read the row: tier, segment, trigger, reason we lose them. Check contact coverage; if 0, enrich before anything else. | AP23: =IFERROR(INDEX(Playbook!$D$4:$D$17,MATCH($AF23,Playbook!$A$4:$A$17,0)),"") -> — | AQ23: =IFERROR(INDEX(Playbook!$E$4:$E$17,MATCH($AF23,Playbook!$A$4:$A$17,0)),"") -> Row read and a contact channel exists | AR23: =IFERROR(INDEX(Playbook!$G$4:$G$17,MATCH($AF23,Playbook!$A$4:$A$17,0)),0) -> 0 | AS23: =IFERROR(INDEX('Pricing & Pilot'!$D$4:$D$6,MATCH($D23,'Pricing & Pilot'!$A$4:$A$6,0)),0) -> 6480 | AT23: =AS23*AR23 -> 0 | AU23: =IF(AL23="","",TODAY()-AL23) | AV23: =IF(AM23="","",IF(AND(AM23<TODAY(),$AF23<>"Customer",$AF23<>"Lost",$AF23<>"Not a fit"),"OVERDUE","")) | AW23: =IF(AV23="OVERDUE","RED",IF($AF23="Not started","—",IF($AF23="Customer","GREEN",IF(OR($AF23="Lost",$AF23="Not a fit"),"CLOSED","AMBER")))) -> —
A24: 23 | B24: B | C24: =IF(OR(B24="A",B24="B"),"Yes","No") -> Yes | D24: S1 | E24: Reformas Garriga De Finques Fornell SL | F24: Reformas Garriga De Finques Fornell | H24: 4335 | I24: Division 43 — specialised construction | J24: S.L. | K24: Granollers | L24: Barcelona | M24: 63.6 | N24: Medium | O24: L0–L1 | P24: target 43.3/43.9 finishing family | Q24: Sector-default only (Verifactu 2027 + quarterly filing cycle; no firm-specific signal in this extraction) | R24: S.L. form matches the reference tenant; CNAE 4335 read as sector-confirming. | U24: No differentiator over the Tier A cohort beyond order of contact — pure reachability risk: someone calls it before we do, or the CNAE/legal-form match turns out wrong on registry check | V24: 938404842 | AC24: https://www.einforma.com/informacion-empresa/reformas-garriga-finques-fornell, https://www.paginasamarillas.es/f/bellavista/reformes-garriga-de-finques-fornell_202517280_000000001.html | AD24: =COUNTA(V24:AA24) -> 1 | AF24: Not started | AO24: =IFERROR(INDEX(Playbook!$C$4:$C$17,MATCH($AF24,Playbook!$A$4:$A$17,0)),"") -> Read the row: tier, segment, trigger, reason we lose them. Check contact coverage; if 0, enrich before anything else. | AP24: =IFERROR(INDEX(Playbook!$D$4:$D$17,MATCH($AF24,Playbook!$A$4:$A$17,0)),"") -> — | AQ24: =IFERROR(INDEX(Playbook!$E$4:$E$17,MATCH($AF24,Playbook!$A$4:$A$17,0)),"") -> Row read and a contact channel exists | AR24: =IFERROR(INDEX(Playbook!$G$4:$G$17,MATCH($AF24,Playbook!$A$4:$A$17,0)),0) -> 0 | AS24: =IFERROR(INDEX('Pricing & Pilot'!$D$4:$D$6,MATCH($D24,'Pricing & Pilot'!$A$4:$A$6,0)),0) -> 3600 | AT24: =AS24*AR24 -> 0 | AU24: =IF(AL24="","",TODAY()-AL24) | AV24: =IF(AM24="","",IF(AND(AM24<TODAY(),$AF24<>"Customer",$AF24<>"Lost",$AF24<>"Not a fit"),"OVERDUE","")) | AW24: =IF(AV24="OVERDUE","RED",IF($AF24="Not started","—",IF($AF24="Customer","GREEN",IF(OR($AF24="Lost",$AF24="Not a fit"),"CLOSED","AMBER")))) -> —
